[2023-02-27 09:55:56,999] {taskinstance.py:1159} INFO - Dependencies all met for <TaskInstance: get_market_overview.push_market_overview scheduled__2023-02-27T05:05:00+00:00 [queued]>
[2023-02-27 09:55:57,019] {taskinstance.py:1159} INFO - Dependencies all met for <TaskInstance: get_market_overview.push_market_overview scheduled__2023-02-27T05:05:00+00:00 [queued]>
[2023-02-27 09:55:57,020] {taskinstance.py:1356} INFO - 
--------------------------------------------------------------------------------
[2023-02-27 09:55:57,020] {taskinstance.py:1357} INFO - Starting attempt 1 of 1
[2023-02-27 09:55:57,020] {taskinstance.py:1358} INFO - 
--------------------------------------------------------------------------------
[2023-02-27 09:55:57,047] {taskinstance.py:1377} INFO - Executing <Task(PythonOperator): push_market_overview> on 2023-02-27 05:05:00+00:00
[2023-02-27 09:55:57,054] {standard_task_runner.py:52} INFO - Started process 10374 to run task
[2023-02-27 09:55:57,057] {standard_task_runner.py:79} INFO - Running: ['***', 'tasks', 'run', 'get_market_overview', 'push_market_overview', 'scheduled__2023-02-27T05:05:00+00:00', '--job-id', '11', '--raw', '--subdir', 'DAGS_FOLDER/get_market_over_view_dag.py', '--cfg-path', '/tmp/tmp080qipy8', '--error-file', '/tmp/tmp7ecuw161']
[2023-02-27 09:55:57,058] {standard_task_runner.py:80} INFO - Job 11: Subtask push_market_overview
[2023-02-27 09:55:57,141] {task_command.py:369} INFO - Running <TaskInstance: get_market_overview.push_market_overview scheduled__2023-02-27T05:05:00+00:00 [running]> on host 5b61798a1106
[2023-02-27 09:55:57,867] {taskinstance.py:1571} INFO - Exporting the following env vars:
AIRFLOW_CTX_DAG_OWNER=***
AIRFLOW_CTX_DAG_ID=get_market_overview
AIRFLOW_CTX_TASK_ID=push_market_overview
AIRFLOW_CTX_EXECUTION_DATE=2023-02-27T05:05:00+00:00
AIRFLOW_CTX_TRY_NUMBER=1
AIRFLOW_CTX_DAG_RUN_ID=scheduled__2023-02-27T05:05:00+00:00
[2023-02-27 09:55:57,871] {logging_mixin.py:115} INFO - Failed to connect
[2023-02-27 09:55:57,878] {taskinstance.py:1889} ERROR - Task failed with exception
Traceback (most recent call last):
  File "/home/airflow/.local/lib/python3.7/site-packages/urllib3/connection.py", line 175, in _new_conn
    (self._dns_host, self.port), self.timeout, **extra_kw
  File "/home/airflow/.local/lib/python3.7/site-packages/urllib3/util/connection.py", line 72, in create_connection
    for res in socket.getaddrinfo(host, port, family, socket.SOCK_STREAM):
  File "/usr/local/lib/python3.7/socket.py", line 752, in getaddrinfo
    for res in _socket.getaddrinfo(host, port, family, type, proto, flags):
socket.gaierror: [Errno -3] Temporary failure in name resolution

During handling of the above exception, another exception occurred:

Traceback (most recent call last):
  File "/home/airflow/.local/lib/python3.7/site-packages/urllib3/connectionpool.py", line 710, in urlopen
    chunked=chunked,
  File "/home/airflow/.local/lib/python3.7/site-packages/urllib3/connectionpool.py", line 386, in _make_request
    self._validate_conn(conn)
  File "/home/airflow/.local/lib/python3.7/site-packages/urllib3/connectionpool.py", line 1040, in _validate_conn
    conn.connect()
  File "/home/airflow/.local/lib/python3.7/site-packages/urllib3/connection.py", line 358, in connect
    self.sock = conn = self._new_conn()
  File "/home/airflow/.local/lib/python3.7/site-packages/urllib3/connection.py", line 187, in _new_conn
    self, "Failed to establish a new connection: %s" % e
urllib3.exceptions.NewConnectionError: <urllib3.connection.HTTPSConnection object at 0x7fde72a8ecd0>: Failed to establish a new connection: [Errno -3] Temporary failure in name resolution

During handling of the above exception, another exception occurred:

Traceback (most recent call last):
  File "/home/airflow/.local/lib/python3.7/site-packages/requests/adapters.py", line 450, in send
    timeout=timeout
  File "/home/airflow/.local/lib/python3.7/site-packages/urllib3/connectionpool.py", line 786, in urlopen
    method, url, error=e, _pool=self, _stacktrace=sys.exc_info()[2]
  File "/home/airflow/.local/lib/python3.7/site-packages/urllib3/util/retry.py", line 592, in increment
    raise MaxRetryError(_pool, url, error or ResponseError(cause))
urllib3.exceptions.MaxRetryError: HTTPSConnectionPool(host='wichart.vn', port=443): Max retries exceeded with url: /wichartapi/wichart/price?type=1 (Caused by NewConnectionError('<urllib3.connection.HTTPSConnection object at 0x7fde72a8ecd0>: Failed to establish a new connection: [Errno -3] Temporary failure in name resolution'))

During handling of the above exception, another exception occurred:

Traceback (most recent call last):
  File "/home/airflow/.local/lib/python3.7/site-packages/airflow/operators/python.py", line 171, in execute
    return_value = self.execute_callable()
  File "/home/airflow/.local/lib/python3.7/site-packages/airflow/operators/python.py", line 189, in execute_callable
    return self.python_callable(*self.op_args, **self.op_kwargs)
  File "/opt/airflow/dags/scripts/get_market_overview.py", line 19, in push_data
    response = requests.get(priceURL, params=params)
  File "/home/airflow/.local/lib/python3.7/site-packages/requests/api.py", line 75, in get
    return request('get', url, params=params, **kwargs)
  File "/home/airflow/.local/lib/python3.7/site-packages/requests/api.py", line 61, in request
    return session.request(method=method, url=url, **kwargs)
  File "/home/airflow/.local/lib/python3.7/site-packages/requests/sessions.py", line 529, in request
    resp = self.send(prep, **send_kwargs)
  File "/home/airflow/.local/lib/python3.7/site-packages/requests/sessions.py", line 645, in send
    r = adapter.send(request, **kwargs)
  File "/home/airflow/.local/lib/python3.7/site-packages/requests/adapters.py", line 519, in send
    raise ConnectionError(e, request=request)
requests.exceptions.ConnectionError: HTTPSConnectionPool(host='wichart.vn', port=443): Max retries exceeded with url: /wichartapi/wichart/price?type=1 (Caused by NewConnectionError('<urllib3.connection.HTTPSConnection object at 0x7fde72a8ecd0>: Failed to establish a new connection: [Errno -3] Temporary failure in name resolution'))
[2023-02-27 09:55:57,894] {taskinstance.py:1400} INFO - Marking task as FAILED. dag_id=get_market_overview, task_id=push_market_overview, execution_date=20230227T050500, start_date=20230227T095557, end_date=20230227T095557
[2023-02-27 09:55:57,913] {standard_task_runner.py:97} ERROR - Failed to execute job 11 for task push_market_overview (HTTPSConnectionPool(host='wichart.vn', port=443): Max retries exceeded with url: /wichartapi/wichart/price?type=1 (Caused by NewConnectionError('<urllib3.connection.HTTPSConnection object at 0x7fde72a8ecd0>: Failed to establish a new connection: [Errno -3] Temporary failure in name resolution')); 10374)
[2023-02-27 09:55:57,952] {local_task_job.py:156} INFO - Task exited with return code 1
[2023-02-27 09:55:58,019] {local_task_job.py:273} INFO - 0 downstream tasks scheduled from follow-on schedule check
