[2023-02-24 08:26:43,188] {taskinstance.py:1159} INFO - Dependencies all met for <TaskInstance: get_market_overview.push_market_overview scheduled__2023-02-23T08:05:00+00:00 [queued]>
[2023-02-24 08:26:43,212] {taskinstance.py:1159} INFO - Dependencies all met for <TaskInstance: get_market_overview.push_market_overview scheduled__2023-02-23T08:05:00+00:00 [queued]>
[2023-02-24 08:26:43,212] {taskinstance.py:1356} INFO - 
--------------------------------------------------------------------------------
[2023-02-24 08:26:43,212] {taskinstance.py:1357} INFO - Starting attempt 1 of 1
[2023-02-24 08:26:43,213] {taskinstance.py:1358} INFO - 
--------------------------------------------------------------------------------
[2023-02-24 08:26:43,255] {taskinstance.py:1377} INFO - Executing <Task(PythonOperator): push_market_overview> on 2023-02-23 08:05:00+00:00
[2023-02-24 08:26:43,265] {standard_task_runner.py:52} INFO - Started process 11762 to run task
[2023-02-24 08:26:43,276] {standard_task_runner.py:79} INFO - Running: ['***', 'tasks', 'run', 'get_market_overview', 'push_market_overview', 'scheduled__2023-02-23T08:05:00+00:00', '--job-id', '4', '--raw', '--subdir', 'DAGS_FOLDER/get_market_over_view_dag.py', '--cfg-path', '/tmp/tmpp0l_x5k6', '--error-file', '/tmp/tmpwq2fiyrr']
[2023-02-24 08:26:43,278] {standard_task_runner.py:80} INFO - Job 4: Subtask push_market_overview
[2023-02-24 08:26:43,398] {task_command.py:369} INFO - Running <TaskInstance: get_market_overview.push_market_overview scheduled__2023-02-23T08:05:00+00:00 [running]> on host 9d6011c1c155
[2023-02-24 08:26:43,610] {taskinstance.py:1571} INFO - Exporting the following env vars:
AIRFLOW_CTX_DAG_OWNER=***
AIRFLOW_CTX_DAG_ID=get_market_overview
AIRFLOW_CTX_TASK_ID=push_market_overview
AIRFLOW_CTX_EXECUTION_DATE=2023-02-23T08:05:00+00:00
AIRFLOW_CTX_TRY_NUMBER=1
AIRFLOW_CTX_DAG_RUN_ID=scheduled__2023-02-23T08:05:00+00:00
[2023-02-24 08:26:43,616] {logging_mixin.py:115} INFO - Failed to connect
[2023-02-24 08:26:43,626] {taskinstance.py:1889} ERROR - Task failed with exception
Traceback (most recent call last):
  File "/home/airflow/.local/lib/python3.7/site-packages/urllib3/connection.py", line 175, in _new_conn
    (self._dns_host, self.port), self.timeout, **extra_kw
  File "/home/airflow/.local/lib/python3.7/site-packages/urllib3/util/connection.py", line 72, in create_connection
    for res in socket.getaddrinfo(host, port, family, socket.SOCK_STREAM):
  File "/usr/local/lib/python3.7/socket.py", line 752, in getaddrinfo
    for res in _socket.getaddrinfo(host, port, family, type, proto, flags):
socket.gaierror: [Errno -3] Temporary failure in name resolution

During handling of the above exception, another exception occurred:

Traceback (most recent call last):
  File "/home/airflow/.local/lib/python3.7/site-packages/urllib3/connectionpool.py", line 710, in urlopen
    chunked=chunked,
  File "/home/airflow/.local/lib/python3.7/site-packages/urllib3/connectionpool.py", line 386, in _make_request
    self._validate_conn(conn)
  File "/home/airflow/.local/lib/python3.7/site-packages/urllib3/connectionpool.py", line 1040, in _validate_conn
    conn.connect()
  File "/home/airflow/.local/lib/python3.7/site-packages/urllib3/connection.py", line 358, in connect
    self.sock = conn = self._new_conn()
  File "/home/airflow/.local/lib/python3.7/site-packages/urllib3/connection.py", line 187, in _new_conn
    self, "Failed to establish a new connection: %s" % e
urllib3.exceptions.NewConnectionError: <urllib3.connection.HTTPSConnection object at 0x7fa7b2ce82d0>: Failed to establish a new connection: [Errno -3] Temporary failure in name resolution

During handling of the above exception, another exception occurred:

Traceback (most recent call last):
  File "/home/airflow/.local/lib/python3.7/site-packages/requests/adapters.py", line 450, in send
    timeout=timeout
  File "/home/airflow/.local/lib/python3.7/site-packages/urllib3/connectionpool.py", line 786, in urlopen
    method, url, error=e, _pool=self, _stacktrace=sys.exc_info()[2]
  File "/home/airflow/.local/lib/python3.7/site-packages/urllib3/util/retry.py", line 592, in increment
    raise MaxRetryError(_pool, url, error or ResponseError(cause))
urllib3.exceptions.MaxRetryError: HTTPSConnectionPool(host='wichart.vn', port=443): Max retries exceeded with url: /wichartapi/wichart/price?type=1 (Caused by NewConnectionError('<urllib3.connection.HTTPSConnection object at 0x7fa7b2ce82d0>: Failed to establish a new connection: [Errno -3] Temporary failure in name resolution'))

During handling of the above exception, another exception occurred:

Traceback (most recent call last):
  File "/home/airflow/.local/lib/python3.7/site-packages/airflow/operators/python.py", line 171, in execute
    return_value = self.execute_callable()
  File "/home/airflow/.local/lib/python3.7/site-packages/airflow/operators/python.py", line 189, in execute_callable
    return self.python_callable(*self.op_args, **self.op_kwargs)
  File "/opt/airflow/dags/scripts/get_market_overview.py", line 19, in push_data
    response = requests.get(priceURL, params=params)
  File "/home/airflow/.local/lib/python3.7/site-packages/requests/api.py", line 75, in get
    return request('get', url, params=params, **kwargs)
  File "/home/airflow/.local/lib/python3.7/site-packages/requests/api.py", line 61, in request
    return session.request(method=method, url=url, **kwargs)
  File "/home/airflow/.local/lib/python3.7/site-packages/requests/sessions.py", line 529, in request
    resp = self.send(prep, **send_kwargs)
  File "/home/airflow/.local/lib/python3.7/site-packages/requests/sessions.py", line 645, in send
    r = adapter.send(request, **kwargs)
  File "/home/airflow/.local/lib/python3.7/site-packages/requests/adapters.py", line 519, in send
    raise ConnectionError(e, request=request)
requests.exceptions.ConnectionError: HTTPSConnectionPool(host='wichart.vn', port=443): Max retries exceeded with url: /wichartapi/wichart/price?type=1 (Caused by NewConnectionError('<urllib3.connection.HTTPSConnection object at 0x7fa7b2ce82d0>: Failed to establish a new connection: [Errno -3] Temporary failure in name resolution'))
[2023-02-24 08:26:43,651] {taskinstance.py:1400} INFO - Marking task as FAILED. dag_id=get_market_overview, task_id=push_market_overview, execution_date=20230223T080500, start_date=20230224T082643, end_date=20230224T082643
[2023-02-24 08:26:43,700] {standard_task_runner.py:97} ERROR - Failed to execute job 4 for task push_market_overview (HTTPSConnectionPool(host='wichart.vn', port=443): Max retries exceeded with url: /wichartapi/wichart/price?type=1 (Caused by NewConnectionError('<urllib3.connection.HTTPSConnection object at 0x7fa7b2ce82d0>: Failed to establish a new connection: [Errno -3] Temporary failure in name resolution')); 11762)
[2023-02-24 08:26:43,726] {local_task_job.py:156} INFO - Task exited with return code 1
[2023-02-24 08:26:43,867] {local_task_job.py:273} INFO - 0 downstream tasks scheduled from follow-on schedule check
[2023-02-26 17:00:20,657] {taskinstance.py:1159} INFO - Dependencies all met for <TaskInstance: get_market_overview.push_market_overview scheduled__2023-02-23T08:05:00+00:00 [queued]>
[2023-02-26 17:00:20,672] {taskinstance.py:1159} INFO - Dependencies all met for <TaskInstance: get_market_overview.push_market_overview scheduled__2023-02-23T08:05:00+00:00 [queued]>
[2023-02-26 17:00:20,672] {taskinstance.py:1356} INFO - 
--------------------------------------------------------------------------------
[2023-02-26 17:00:20,672] {taskinstance.py:1357} INFO - Starting attempt 1 of 1
[2023-02-26 17:00:20,673] {taskinstance.py:1358} INFO - 
--------------------------------------------------------------------------------
[2023-02-26 17:00:20,700] {taskinstance.py:1377} INFO - Executing <Task(PythonOperator): push_market_overview> on 2023-02-23 08:05:00+00:00
[2023-02-26 17:00:20,707] {standard_task_runner.py:52} INFO - Started process 589 to run task
[2023-02-26 17:00:20,713] {standard_task_runner.py:79} INFO - Running: ['***', 'tasks', 'run', 'get_market_overview', 'push_market_overview', 'scheduled__2023-02-23T08:05:00+00:00', '--job-id', '2', '--raw', '--subdir', 'DAGS_FOLDER/get_market_over_view_dag.py', '--cfg-path', '/tmp/tmp8c6mn5kf', '--error-file', '/tmp/tmp7ladtxgl']
[2023-02-26 17:00:20,714] {standard_task_runner.py:80} INFO - Job 2: Subtask push_market_overview
[2023-02-26 17:00:20,797] {task_command.py:369} INFO - Running <TaskInstance: get_market_overview.push_market_overview scheduled__2023-02-23T08:05:00+00:00 [running]> on host 5b61798a1106
[2023-02-26 17:00:20,915] {taskinstance.py:1571} INFO - Exporting the following env vars:
AIRFLOW_CTX_DAG_OWNER=***
AIRFLOW_CTX_DAG_ID=get_market_overview
AIRFLOW_CTX_TASK_ID=push_market_overview
AIRFLOW_CTX_EXECUTION_DATE=2023-02-23T08:05:00+00:00
AIRFLOW_CTX_TRY_NUMBER=1
AIRFLOW_CTX_DAG_RUN_ID=scheduled__2023-02-23T08:05:00+00:00
[2023-02-26 17:00:22,394] {logging_mixin.py:115} INFO - (1062, "Duplicate entry '2023-02-26 00:00:00-Dow Jones' for key 'market_overview.PRIMARY'")
[2023-02-26 17:00:22,949] {logging_mixin.py:115} INFO - (1062, "Duplicate entry '2023-02-26 00:00:00-DAX' for key 'market_overview.PRIMARY'")
[2023-02-26 17:00:23,468] {logging_mixin.py:115} INFO - (1062, "Duplicate entry '2023-02-26 00:00:00-FTSE 100' for key 'market_overview.PRIMARY'")
[2023-02-26 17:00:23,757] {logging_mixin.py:115} INFO - (1062, "Duplicate entry '2023-02-26 00:00:00-NI225' for key 'market_overview.PRIMARY'")
[2023-02-26 17:00:24,929] {logging_mixin.py:115} INFO - (1062, "Duplicate entry '2023-02-26 00:00:00-Crude Oil (USD/lb)' for key 'market_overview.PRIMARY'")
[2023-02-26 17:00:25,191] {logging_mixin.py:115} INFO - (1062, "Duplicate entry '2023-02-26 00:00:00-Gold (USD/t oz)' for key 'market_overview.PRIMARY'")
[2023-02-26 17:00:25,443] {logging_mixin.py:115} INFO - (1062, "Duplicate entry '2023-02-26 00:00:00-Natural Gas (USD/Mmbtu)' for key 'market_overview.PRIMARY'")
[2023-02-26 17:00:25,686] {logging_mixin.py:115} INFO - (1062, "Duplicate entry '2023-02-26 00:00:00-Steel (USD/lb)' for key 'market_overview.PRIMARY'")
[2023-02-26 17:00:25,942] {logging_mixin.py:115} INFO - (1062, "Duplicate entry '2023-02-26 00:00:00-Coal (USD/lb)' for key 'market_overview.PRIMARY'")
[2023-02-26 17:00:26,192] {logging_mixin.py:115} INFO - (1062, "Duplicate entry '2023-02-26 00:00:00-Rubber (SGD/kg)' for key 'market_overview.PRIMARY'")
[2023-02-26 17:00:26,433] {logging_mixin.py:115} INFO - (1062, "Duplicate entry '2023-02-26 00:00:00-Sugar (USD/lb)' for key 'market_overview.PRIMARY'")
[2023-02-26 17:00:26,750] {logging_mixin.py:115} INFO - (1062, "Duplicate entry '2023-02-26 00:00:00-Cotton (USD/lb)' for key 'market_overview.PRIMARY'")
[2023-02-26 17:00:27,351] {logging_mixin.py:115} INFO - (1062, "Duplicate entry '2023-02-26 00:00:00-Bitcoin' for key 'market_overview.PRIMARY'")
[2023-02-26 17:00:27,696] {logging_mixin.py:115} INFO - (1062, "Duplicate entry '2023-02-26 00:00:00-Dollar Index' for key 'market_overview.PRIMARY'")
[2023-02-26 17:00:28,129] {logging_mixin.py:115} INFO - (1062, "Duplicate entry '2023-02-26 00:00:00-USD/VND' for key 'market_overview.PRIMARY'")
[2023-02-26 17:00:28,364] {logging_mixin.py:115} INFO - (1062, "Duplicate entry '2023-02-26 00:00:00-USD/CNY' for key 'market_overview.PRIMARY'")
[2023-02-26 17:00:28,863] {logging_mixin.py:115} INFO - (1062, "Duplicate entry '2023-02-26 00:00:00-USD/RUB' for key 'market_overview.PRIMARY'")
[2023-02-26 17:00:29,468] {logging_mixin.py:115} INFO - (1062, "Duplicate entry '2023-02-26 00:00:00-USD/JPY' for key 'market_overview.PRIMARY'")
[2023-02-26 17:00:29,468] {logging_mixin.py:115} INFO - DONE!!!
[2023-02-26 17:00:29,469] {python.py:173} INFO - Done. Returned value was: None
[2023-02-26 17:00:29,482] {taskinstance.py:1400} INFO - Marking task as SUCCESS. dag_id=get_market_overview, task_id=push_market_overview, execution_date=20230223T080500, start_date=20230226T170020, end_date=20230226T170029
[2023-02-26 17:00:29,508] {local_task_job.py:156} INFO - Task exited with return code 0
[2023-02-26 17:00:29,527] {local_task_job.py:273} INFO - 0 downstream tasks scheduled from follow-on schedule check
